<?xml version="1.0"?>

<robot 
  xmlns:controller="http://playerstage.sourceforge.net/gazebo/xmlschema/#controller" 
  xmlns:interface="http://ros.org/wiki/xacro" 
  xmlns:sensor="http://playerstage.sourceforge.net/gazebo/xmlschema/#sensor" 
  xmlns:xacro="http://ros.org/wiki/xacro">
  
  <xacro:include filename="$(find hector_tracked_vehicles_description)/urdf/jasmine_2018_ugv_arm.gazebo.xacro" />
  <xacro:include filename="$(find hector_sensors_description)/urdf/generic_camera.urdf.xacro" />

  <xacro:property name="XM430_W350_max_effort" value="4.1" />
  <xacro:property name="XM540_W270_max_effort" value="10.6" />

  <xacro:property name="XM430_W350_max_velocity" value="4.81710873" />
  <xacro:property name="XM540_W270_max_velocity" value="3.1415926499999998" />

  <xacro:property name="joint_damping" value="0.2" />
  <xacro:property name="joint_friction" value="0.5" />
  
  <xacro:macro name="manipulator_arm_macro" params="parent *origin">
    <joint name="arm_base_joint" type="fixed">
      <xacro:insert_block name="origin" />
      <parent link="${parent}" />
      <child link="arm_base_link" />
    </joint>

    <link name="arm_base_link">
      <visual>
        <origin xyz="0 0.0 0.0" rpy="0.0 0.0 0.0" />
        <geometry>
          <mesh filename="package://hector_tracked_vehicles_description/meshes/jasmine_ugv/arm/link0.stl" scale="0.001 0.001 0.001" />
        </geometry>
        <material name="DarkGrey">
          <color rgba="0.3 0.3 0.3 1" />
        </material>
      </visual>
      
      <collision>
        <origin xyz="0.0125 0.0 0.02" rpy="0.0 0.0 0.0" />
        <geometry>
          <box size="0.055 0.03 0.04" />
        </geometry>
      </collision>

      <inertial>
        <origin xyz="0.0129 0.00024 0.01759" rpy="0.0 0.0 0.0" />
        <mass value="0.082" />
        <inertia ixx="4.8545E-5"   ixy="-2.17E-7"    ixz="-4.16E-7"
                                    iyy="2.5118E-5"    iyz="1.751E-5"
                                                        izz="4.077E-6" />
      </inertial>
    </link>

    <joint name="arm_yaw_joint" type="revolute">
      <origin xyz="0.0 0 0.036" rpy="0.0 0.0 ${pi / 2}" />
      <axis xyz="0 0 1" />
      <limit lower="${-pi / 2}" upper="${pi / 2}" effort="${XM430_W350_max_effort}" velocity="${XM430_W350_max_velocity}" />
      <parent link="arm_base_link" />
      <child link="arm_yaw_link" />
      <dynamics friction="${joint_friction}" damping="${joint_damping}" />
    </joint>

    <link name="arm_yaw_link">
      <visual>
        <origin xyz="0 0.0 0.0" rpy="0.0 0.0 0.0" />
        <geometry>
          <mesh filename="package://hector_tracked_vehicles_description/meshes/jasmine_ugv/arm/link1.stl" scale="0.001 0.001 0.001" />
        </geometry>
        <material name="DarkGrey">
          <color rgba="0.3 0.3 0.3 1" />
        </material>
      </visual>
      
      <collision>
        <origin xyz="0.0 -0.0025 0.035" rpy="0.0 0.0 0.0" />
        <geometry>
          <box size="0.04 0.055 0.07" />
        </geometry>
      </collision>

      <inertial>
        <origin xyz="0.0 -0.00064 0.03439" rpy="0.0 0.0 0.0" />
        <mass value="0.176" />
        <inertia ixx="-9.361E-6"   ixy="0.0"     ixz="0.0"
                                    iyy="-1.1746E-5"     iyz="2.42E-7"
                                                        izz="4.445E-6" />
      </inertial>
    </link>

    <joint name="arm_pitch_joint_0" type="revolute">
      <origin xyz="0.0 0.0 0.0515" rpy=" ${pi/2} 0.0 0.0" />
      <axis xyz="0 0 1" />
      <limit lower="${-pi / 2}" upper="${pi / 2}" effort="${XM540_W270_max_effort}" velocity="${XM540_W270_max_velocity}" />
      <parent link="arm_yaw_link" />
      <child link="arm_pitch_link_0" />
      <dynamics friction="${joint_friction}" damping="${joint_damping}" />
    </joint>

    <link name="arm_pitch_link_0">
      <visual>
        <origin xyz="0.0 0.0 0.0" rpy="0.0 0.0 0.0" />
        <geometry>
          <mesh filename="package://hector_tracked_vehicles_description/meshes/jasmine_ugv/arm/link2.stl" scale="0.001 0.001 0.001" />
        </geometry>
        <material name="DarkGrey">
          <color rgba="0.3 0.3 0.3 1" />
        </material>
      </visual>
      
      <collision>
        <origin xyz="0.0 0.01 0.025" rpy="0.0 0.0 0.0" />
        <geometry>
          <box size="0.035 0.045 0.01" />
        </geometry>
      </collision>

      <collision>
        <origin xyz="0.0 0.01 -0.025" rpy="0.0 0.0 0.0" />
        <geometry>
          <box size="0.035 0.045 0.01" />
        </geometry>
      </collision>
      
     <collision>
        <origin xyz="0.01 0.25 0.0" rpy="0.0 0.0 0.0" />
        <geometry>
          <box size="0.06 0.04 0.04" />
        </geometry>
     </collision>
      
    <collision>
        <origin xyz="0.0 0.13 0.0" rpy="0.0 0.0 0.0" />
        <geometry>
          <box size="0.04 0.2 0.04" />
        </geometry>
      </collision>

      <inertial>
        <origin xyz="0.00692 0.18362 0.00028" rpy="0.0 0.0 0.0" />
        <mass value="0.172" />
        <inertia ixx="0.001359662"    ixy="7.8685E-5"    ixz="-2.1E-7"
                                      iyy="3.584E-5"    iyz="3.533E-6"
                                                          izz="0.00134845" />
      </inertial>
    </link>

    <joint name="arm_pitch_joint_1" type="revolute">
      <origin xyz="0.026 0.2517 0.0" rpy="0.0 0.0 ${-pi}" />
      <axis xyz="0 0 1" />
      <limit lower="${-pi/2}" upper="${pi/2}" effort="${XM430_W350_max_effort}" velocity="${XM430_W350_max_velocity}" />
      <parent link="arm_pitch_link_0" />
      <child link="arm_pitch_link_1" />
      <dynamics friction="${joint_friction}" damping="${joint_damping}" />
    </joint>

    <link name="arm_pitch_link_1">
      <visual>
        <origin xyz="0.0 0.0 0.0" rpy="0.0 0.0 0.0" />
        <geometry>
          <mesh filename="package://hector_tracked_vehicles_description/meshes/jasmine_ugv/arm/link3.stl" scale="0.001 0.001 0.001" />
        </geometry>
        <material name="DarkGrey">
          <color rgba="0.3 0.3 0.3 1" />
        </material>
      </visual>

      <collision>
        <origin xyz="-0.01 0.0 0.02" rpy="0.0 0.0 0.0" />
        <geometry>
          <box size="0.04 0.03 0.0075" />
        </geometry>
      </collision>

      <collision>
        <origin xyz="-0.01 0.0 -0.02" rpy="0.0 0.0 0.0" />
        <geometry>
          <box size="0.04 0.03 0.0075" />
        </geometry>
      </collision>
      <collision>
        <origin xyz="-0.09 0.0 0.0" rpy="0.0 0.0 0.0" />
        <geometry>
          <box size="0.14 0.03 0.04" />
        </geometry>
      </collision>
      
      <collision>
        <origin xyz="-0.182 -0.004 0.0" rpy="0.0 0.0 0.0" />
        <geometry>
          <box size="0.055 0.035 0.04" />
        </geometry>
      </collision>

      <inertial>
        <origin xyz="-0.14163 -0.00294 0.00033" rpy="0.0 0.0 0.0" />
        <mass value="0.147" />
        <inertia ixx="2.3437E-5"   ixy="7.946E-6"      ixz="-1.54E-6"
                                    iyy="0.00051703"     iyz="-2.64E-7"
                                                          izz="0.000506424" />
      </inertial>
    </link>

    <joint name="arm_pitch_joint_2" type="revolute">
      <origin xyz="-0.1967 -0.004 0.0" rpy="0.0 0.0 0.0" />
      <axis xyz="0 0 1" />
      <limit lower="${-pi / 2}" upper="${pi / 2}" effort="${XM430_W350_max_effort}" velocity="${XM430_W350_max_velocity}" />
      <parent link="arm_pitch_link_1" />
      <child link="arm_pitch_link_2" />
      <dynamics friction="${joint_friction}" damping="${joint_damping}" />
    </joint>
    
    <link name="arm_pitch_link_2">
      <visual>
        <origin xyz="0.0 0.0 0.0" rpy="0.0 0.0 0.0" />
        <geometry>
          <mesh filename="package://hector_tracked_vehicles_description/meshes/jasmine_ugv/arm/link4.stl" scale="0.001 0.001 0.001" />
        </geometry>
        <material name="DarkGrey">
          <color rgba="0.3 0.3 0.3 1" />
        </material>
      </visual>

      <collision>
        <origin xyz="-0.01 0.0 0.02" rpy="0.0 0.0 0.0" />
        <geometry>
          <box size="0.04 0.03 0.0075" />
        </geometry>
      </collision>

      <collision>
        <origin xyz="-0.01 0.0 -0.02" rpy="0.0 0.0 0.0" />
        <geometry>
          <box size="0.04 0.03 0.0075" />
        </geometry>
      </collision>
      <collision>
        <origin xyz="-0.045 0.0 0.0" rpy="0.0 0.0 0.0" />
        <geometry>
          <box size="0.05 0.035 0.05" />
        </geometry>
      </collision>

      <inertial>
        <origin xyz="-0.0475 -0.0002 0.00076" rpy="0.0 0.0 0.0" />
        <mass value="0.09715" />
        <inertia ixx="1e-6"   ixy="-0.000017591"      ixz="0.000000113"
                                    iyy="1e-6"     iyz="-0.000000215"
                                                          izz="1e-6" />
      </inertial>
    </link>
        
    <joint name="arm_roll_joint" type="revolute">
      <origin xyz="-0.073 0.0 -0.012" rpy="${pi/2} 0.0 ${-pi/2}" />
      <axis xyz="0 0 1" />
      <limit lower="${-pi}" upper="${162.976*pi/180}" effort="${XM430_W350_max_effort}" velocity="${XM430_W350_max_velocity}" />
      <parent link="arm_pitch_link_2" />
      <child link="arm_roll_link" />
      <dynamics friction="${joint_friction}" damping="${joint_damping}" />
    </joint>
    
    <link name="arm_roll_link">
      <visual>
        <origin xyz="0.0 0.0 0.0" rpy="0.0 0.0 0.0" />
        <geometry>
          <mesh filename="package://hector_tracked_vehicles_description/meshes/jasmine_ugv/arm/link5.stl" scale="0.001 0.001 0.001" />
        </geometry>
        <material name="DarkGrey">
          <color rgba="0.3 0.3 0.3 1" />
        </material>
      </visual>

      <collision>
        <origin xyz="0.0 0.004 0.0" rpy="0.0 0.0 0.0" />
        <geometry>
          <box size="0.025 0.06 0.0075" />
        </geometry>
      </collision>
      
      <collision>
        <origin xyz="0.0 0.031 0.015" rpy="0.0 0.0 0.0" />
        <geometry>
          <box size="0.025 0.0075 0.035" />
        </geometry>
      </collision>
      
      <collision>
        <origin xyz="0.0 -0.022 0.015" rpy="0.0 0.0 0.0" />
        <geometry>
          <box size="0.025 0.0075 0.035" />
        </geometry>
      </collision>

      <inertial>
        <origin xyz="0.00003 0.00453 0.01105" rpy="0.0 0.0 0.0" />
        <mass value="0.012667" />
        <inertia ixx="0.000009292"   ixy="0.000000012"      ixz="0.000000008"
                                    iyy="0.000003471"     iyz="0.000000621"
                                                          izz="0.00000707" />
      </inertial>
    </link>

    <joint name="gripper_palm_joint" type="fixed">
      <origin xyz="0.0 0.0 0.0" rpy="0.0 0.0 0.0" />
      <parent link="arm_roll_link" />
      <child link="gripper_palm_link" />
    </joint>
    
    <link name="gripper_palm_link">
      <visual>
        <origin xyz="0.0 0.0 0.0" rpy="0.0 0.0 0.0" />
        <geometry>
          <mesh filename="package://hector_tracked_vehicles_description/meshes/jasmine_ugv/gripper/gripper_palm.stl" scale="0.001 0.001 0.001" />
        </geometry>
        <material name="DarkGrey">
          <color rgba="0.3 0.3 0.3 1" />
        </material>
      </visual>
      
      <collision>
        <origin xyz="0.0 0.0 0.0225" rpy="0.0 0.0 0.0" />
        <geometry>
          <box size="0.05 0.055 0.05" />
        </geometry>
      </collision>

      <collision>
        <origin xyz="-0.03 0.0 0.0325" rpy="0.0 0.0 ${pi/2}" />
        <geometry>
          <box size="0.055 0.02 0.0685" />
        </geometry>
      </collision>

      <collision>
        <origin xyz="0.03 0.0 0.0325" rpy="0.0 0.0 ${pi/2}" />
        <geometry>
          <box size="0.055 0.02 0.0685" />
        </geometry>
      </collision>

      <collision>
        <origin xyz="-0.03 0.02 0.04" rpy="${-pi/2} 0.0 ${pi/2}" />
        <geometry>
          <cylinder length="0.02" radius="0.028" />
        </geometry>
      </collision>
      
      <collision>
        <origin xyz="-0.03 -0.02 0.04" rpy="${-pi/2} 0.0 ${pi/2}" />
        <geometry>
          <cylinder length="0.02" radius="0.028" />
        </geometry>
      </collision>

      <collision>
        <origin xyz="0.03 0.02 0.04" rpy="${-pi/2} 0.0 ${pi/2}" />
        <geometry>
          <cylinder length="0.02" radius="0.028" />
        </geometry>
      </collision>
      
      <collision>
        <origin xyz="0.03 -0.02 0.04" rpy="${-pi/2} 0.0 ${pi/2}" />
        <geometry>
          <cylinder length="0.02" radius="0.028" />
        </geometry>
      </collision>
	  
      <inertial>
      
        <origin xyz="0.00018 0.00265 0.03088" rpy="0.0 0.0 0.0" />
        <mass value="0.155" />
        <inertia ixx="0.000058905"    ixy="-0.000001039"    ixz="-0.000015872"
                                      iyy="0.000129197"    iyz="-0.000002084"
                                                          izz="0.000106087" />
      </inertial>
    </link>
    
    <joint name="gripper_servo_joint" type="revolute">
      <origin xyz="0.024 0.01612 0.01625" rpy="${pi/2} 0.0 ${pi / 2}" />
      <axis xyz="0 0 1" />
      <limit lower="${-M_PI/2}" upper="${112 * M_PI/ 180}" effort="${XM430_W350_max_effort}" velocity="${XM430_W350_max_velocity}" />
      <parent link="gripper_palm_link" />
      <child link="gripper_servo_link" />
      <dynamics friction="${0.01*joint_friction}" damping="${0.01*joint_damping}" />
    </joint>
    
    <link name="gripper_servo_link">
      <inertial>
        <origin xyz="0.0 0.0 0.0" rpy="0.0 0.0 0.0" />
        <mass value="0.001" />
        <inertia ixx="1.0e-06" ixy="0.0"     ixz="0.0"
                              iyy="1.0e-06"  iyz="0.0"
                                            izz="1.0e-06" />
      </inertial>
      
      <visual>
        <origin xyz="0 0.0 0.0" rpy="0.0 0.0 0.0" />
        <geometry>
          <cylinder length="0.01" radius="0.01" />
        </geometry>
      </visual>
      
      <collision>
        <origin xyz="0 0.0 0.0" rpy="0.0 0.0 0.0" />
        <geometry>
          <cylinder length="0.01" radius="0.01" />
        </geometry>
      </collision>
    </link>

    <!-- virtual endeffector joint -->
    <joint name="gripper_grasp_joint" type="fixed">
      <origin xyz="0.0 0.0 0.15" rpy="0.0 0.0 0.0"/>
      <parent link="gripper_palm_link"/>
      <child link="gripper_grasp_link"/>
    </joint> 

    <link name="gripper_grasp_link">
<!--      <visual>
        <origin xyz="0.0 0.0 0.0" rpy="0.0 0.0 0.0"/>
        <geometry>
          <sphere radius="0.005" />
        </geometry>
        <material name="red"/>
      </visual>

      <inertial>
        <origin xyz="0.0 0.0 0.0" rpy="0.0 0.0 0.0"/>
        <mass value="0.0001"/>
      <inertia ixx="1.0e-10" ixy="0.0" ixz="0.0" iyy="1.0e-10" iyz="0.0" izz="1.0e-10" />
      </inertial>-->
    </link>
    
	  <!-- gripper finger -->
    <joint name="gripper_finger_joint_0" type="continuous">
      <origin xyz="0.0 -0.020125 0.04108" rpy="0.0 ${pi / 2} 0.0" />
      <axis xyz="0 0 1" />
      <limit lower="${-0.95*pi}" upper="${0.95*pi}" effort="${XM430_W350_max_effort}" velocity="${XM430_W350_max_velocity}" />
      <parent link="gripper_palm_link" />
      <child link="gripper_finger_link_0" />
      <mimic joint="gripper_servo_joint" multiplier="${-8 / 23}" offset="${-M_PI/2 * 8/23}" />
      <dynamics friction="${joint_friction}" damping="${joint_damping}" />
    </joint>
    
    <link name="gripper_finger_link_0">
      <visual>
        <origin xyz="0.0 0.0 0.0" rpy="0.0 0.0 0.0" />
        <geometry>
          <mesh filename="package://hector_tracked_vehicles_description/meshes/jasmine_ugv/gripper/gripper_finger.stl" scale="-0.001 0.001 0.001" />
        </geometry>
        <material name="DarkGrey">
          <color rgba="0.3 0.3 0.3 1" />
        </material>
      </visual>

      <collision>
        <origin xyz="-0.045 -0.055 0.0" rpy="0.0 0.0 ${57 * pi / 180}" />
        <geometry>
          <box size="0.095 0.005 0.03" />
        </geometry>
      </collision>
      
      <collision>
        <origin xyz="-0.0275 -0.0725 0.0" rpy="0.0 0.0 ${29* pi / 180}" />
        <geometry>
          <box size="0.095 0.005 0.03" />
        </geometry>
      </collision>
      
      <collision>
        <origin xyz="-0.005 -0.035 0.0" rpy="0.0 0.0 ${-42 * pi / 180}" />
        <geometry>
          <box size="0.05 0.005 0.03" />
        </geometry>
      </collision>
      
      <collision>
        <origin xyz="0.0 -0.025 0.0" rpy="0.0 0.0 ${45 * pi / 180}" />
        <geometry>
          <box size="0.03 0.03 0.06" />
        </geometry>
      </collision>

      <inertial>
        <origin xyz="0.0118 -0.03269 0.00029" rpy="0.0 0.0 0.0" />
        <mass value="0.029" />
        <inertia ixx="0.00006267"   ixy="-0.000021787" ixz="-0.000000201"
                                        iyy="0.000044811"  iyz="0.00000006"
                                                              izz="0.000065514" />
      </inertial>
    </link>
    
    <joint name="gripper_finger_joint_1" type="continuous">
      <origin xyz="0.0 0.020125 0.04108" rpy="0.0 ${pi / 2} ${pi}" />
      <axis xyz="0 0 1" />
      <limit lower="${-0.95*pi}" upper="${0.95*pi}" effort="${XM430_W350_max_effort}" velocity="${XM430_W350_max_velocity}" />
      <parent link="gripper_palm_link" />
      <child link="gripper_finger_link_1" />
      <mimic joint="gripper_servo_joint" multiplier="${-8 / 23}" offset="${-M_PI/2 * 8/23}" />
      <dynamics friction="${joint_friction}" damping="${joint_damping}" />
    </joint>
    
    <link name="gripper_finger_link_1">
      <visual>
        <origin xyz="0.0 0.0 0.0" rpy="0.0 0.0 0.0" />
        <geometry>
          <mesh filename="package://hector_tracked_vehicles_description/meshes/jasmine_ugv/gripper/gripper_finger.stl" scale="-0.001 0.001 0.001" />
        </geometry>
        <material name="DarkGrey">
          <color rgba="0.3 0.3 0.3 1" />
        </material>
      </visual>
      
      <collision>
        <origin xyz="-0.045 -0.055 0.0" rpy="0.0 0.0 ${57 * pi / 180}" />
        <geometry>
          <box size="0.095 0.005 0.03" />
        </geometry>
      </collision>
      
      <collision>
        <origin xyz="-0.0275 -0.0725 0.0" rpy="0.0 0.0 ${29* pi / 180}" />
        <geometry>
          <box size="0.095 0.005 0.03" />
        </geometry>
      </collision>
      
      <collision>
        <origin xyz="-0.005 -0.035 0.0" rpy="0.0 0.0 ${-42 * pi / 180}" />
        <geometry>
          <box size="0.05 0.005 0.03" />
        </geometry>
      </collision>
      
      <collision>
        <origin xyz="0.0 -0.025 0.0" rpy="0.0 0.0 ${45 * pi / 180}" />
        <geometry>
          <box size="0.03 0.03 0.06" />
        </geometry>
      </collision>

      <inertial>
        <origin xyz="0.0118 -0.03269 0.00029" rpy="0.0 0.0 0.0" />
        <mass value="0.029" />
        <inertia ixx="0.00006267"   ixy="-0.000021787" ixz="-0.000000201"
                                        iyy="0.000044811"  iyz="0.00000006"
                                                              izz="0.000065514" />
      </inertial>
    </link>
    
    <xacro:generic_camera name="gripper_cam" parent="gripper_palm_link" ros_topic="/gripper_cam/image_raw" cam_info_topic="/gripper_cam/camera_info" update_rate="15" res_x="640" res_y="480" image_format="R8G8B8" hfov="60">
      <origin xyz="0 0 0" rpy="${pi} ${-pi/2} ${-pi/2}"/>
    </xacro:generic_camera>
 
  </xacro:macro>
</robot>
