<?xml version="1.0"?>

<robot xmlns:xacro="http://www.ros.org/wiki/xacro">
  
  <!-- Properties (Constants) -->
  <xacro:property name="M_PI" value="3.14159" />
  
  <!--<xacro:property name="wheel_radius" value="0.185" />-->
  <!--<xacro:property name="wheel_size_y" value="0.0824" />-->
  <!-- half of wheel width + half of socket width + gap -->
  <xacro:property name="wheel_offset_z" value="-0.112" />
  <!-- wheel_radius - socket height -->
  
  <xacro:macro name="tracked_wheel" params="parent prefix offset_x offset_y offset_z reflect wheel_radius">
    
    <joint name="${prefix}_wheel_joint" type="continuous">
      <origin xyz="${offset_x } ${offset_y * reflect} ${offset_z}" rpy="0 0 0" />
      <parent link="${parent}" />
      <child link="${prefix}_wheel_link" />
      <axis xyz="0 1 0" />
      <limit effort="100" velocity="100" />
      <joint_properties damping="0.0" friction="0.0" />
      <anchor xyz="0 0 0" />
    </joint>    
    
    <link name="${prefix}_wheel_link">
      <inertial>
        <mass value="0.01" />
        <origin xyz=" 0 0 0 " />
        <inertia  ixx="0.00012411765597" ixy="0.0" ixz="0.0"
                 iyy="0.00015218160428" iyz="0.0"
                 izz="0.00011763977943" />
        </inertial>
        
        <collision>
          <origin xyz="0 0 0" rpy="${-M_PI/2} 0 0" />
          <geometry>
            <cylinder radius="${wheel_radius}" length="${wheel_size_y}" />
            <!--<box size="1.0 0.5 0.1" />-->
          </geometry>
          <!--<material name="MTWheelColMat"/>-->
        </collision>
      </link>
      
      <gazebo reference="${prefix}_wheel_link" >
        <mu1>1.0</mu1>
        <mu2>1.0</mu2>
        <kp>1000000.0</kp>
        <kd>100.0</kd>
        <minDepth>0.001</minDepth>
        <maxVel>1.0</maxVel>         
        <!--<fdir1>1 0 0</fdir1>-->
        <!--<maxVel>1.0</maxVel>-->
      </gazebo>
      
      <transmission type="pr2_mechanism_model/SimpleTransmission" name="${prefix}_wheel_trans">
        <actuator name="${prefix}_motor_link" />
        <joint name="${prefix}_wheel_joint" />
        <mechanicalReduction>1.0</mechanicalReduction>
        <motorTorqueConstant>1</motorTorqueConstant>
      </transmission>
      
    </xacro:macro>

</robot>